<!DOCTYPE html>
<html lang="en">

<head>
    <meta charset="UTF-8">
    <meta name="viewport" content="width=device-width, initial-scale=1.0">
    <meta http-equiv="X-UA-Compatible" content="ie=edge">
    <title>Document</title>
</head>

<body>
    <script>

        Promise.resolve()
            .then(() => {
                return new Error('error!!!')
            })
            .then((res) => {
                console.log('then: ', res)
            })
            .catch((err) => {
                console.log('catch: ', err)
            })
            
    </script>

    运行结果：
    then: Error: error!!!
    at Promise.resolve.then (...)
    at ...解释：.then 或者 .catch 中 return 一个 error 对象并不会抛出错误，所以不会被后续的 .catch 捕获，需要改成其中一种：

    return Promise.reject(new Error('error!!!'))

    throw new Error('error!!!')因为返回任意一个非 promise 的值都会被包裹成 promise 对象，

    即 return new Error('error!!!') 等价于 return Promise.resolve(new Error('error!!!'))。



</body>

</html>
