<!DOCTYPE html>
<html lang="en">

<head>
    <meta charset="UTF-8">
    <meta name="viewport" content="width=device-width, initial-scale=1.0">
    <meta http-equiv="X-UA-Compatible" content="ie=edge">
    <title>Document</title>
</head>

<body>

<!-- --------------------------------------------------------------------------------- -->

  Async 函数的错误处理

  async 函数的语法不难，难在错误处理上。

  先来看下面的例子：

  <script>

      let a;

      async function f() {
          await Promise.reject('error');
          a = await 1; // 这段 await 并没有执行
      }

      f().then(v => console.log(a));

  </script>

  如上面所示，当 async 函数中只要一个 await 出现 reject 状态，则后面的 await 都不会被执行。

  解决办法：可以添加 try/catch。

<script>

    // 正确的写法
    let a;
    async function correct() {
        try {
            await Promise.reject('error')
        } catch (error) {
            console.log(error);
        }

        a = await 1;

        return a;

    }

    correct().then(v => console.log(a)); // 1

    // 如果有多个 await 则可以将其都放在 try / catch 中。

</script>

<!-- --------------------------------------------------------------------------------- -->


</body>

</html>
